[2024-07-21 03:42:08,404] {taskinstance.py:896} INFO - Dependencies all met for <TaskInstance: ETL_task.caculate_square_amount 2021-08-11T00:00:00+00:00 [queued]>
[2024-07-21 03:42:08,424] {taskinstance.py:896} INFO - Dependencies all met for <TaskInstance: ETL_task.caculate_square_amount 2021-08-11T00:00:00+00:00 [queued]>
[2024-07-21 03:42:08,424] {taskinstance.py:1087} INFO - 
--------------------------------------------------------------------------------
[2024-07-21 03:42:08,425] {taskinstance.py:1088} INFO - Starting attempt 1 of 2
[2024-07-21 03:42:08,425] {taskinstance.py:1089} INFO - 
--------------------------------------------------------------------------------
[2024-07-21 03:42:08,436] {taskinstance.py:1107} INFO - Executing <Task(PythonOperator): caculate_square_amount> on 2021-08-11T00:00:00+00:00
[2024-07-21 03:42:08,441] {standard_task_runner.py:52} INFO - Started process 288 to run task
[2024-07-21 03:42:08,447] {standard_task_runner.py:76} INFO - Running: ['***', 'tasks', 'run', 'ETL_task', 'caculate_square_amount', '2021-08-11T00:00:00+00:00', '--job-id', '196', '--pool', 'default_pool', '--raw', '--subdir', 'DAGS_FOLDER/ELT.py', '--cfg-path', '/tmp/tmp30f7e0q6', '--error-file', '/tmp/tmp4b7q2e1v']
[2024-07-21 03:42:08,448] {standard_task_runner.py:77} INFO - Job 196: Subtask caculate_square_amount
[2024-07-21 03:42:08,503] {logging_mixin.py:104} INFO - Running <TaskInstance: ETL_task.caculate_square_amount 2021-08-11T00:00:00+00:00 [running]> on host abd747f4a187
[2024-07-21 03:42:08,595] {taskinstance.py:1302} INFO - Exporting the following env vars:
AIRFLOW_CTX_DAG_EMAIL=trihx2003@gmail.com
AIRFLOW_CTX_DAG_OWNER=***
AIRFLOW_CTX_DAG_ID=ETL_task
AIRFLOW_CTX_TASK_ID=caculate_square_amount
AIRFLOW_CTX_EXECUTION_DATE=2021-08-11T00:00:00+00:00
AIRFLOW_CTX_DAG_RUN_ID=scheduled__2021-08-11T00:00:00+00:00
[2024-07-21 03:42:08,635] {taskinstance.py:1501} ERROR - Task failed with exception
Traceback (most recent call last):
  File "/home/airflow/.local/lib/python3.6/site-packages/pandas/core/ops/array_ops.py", line 143, in na_arithmetic_op
    result = expressions.evaluate(op, left, right)
  File "/home/airflow/.local/lib/python3.6/site-packages/pandas/core/computation/expressions.py", line 233, in evaluate
    return _evaluate(op, op_str, a, b)  # type: ignore
  File "/home/airflow/.local/lib/python3.6/site-packages/pandas/core/computation/expressions.py", line 68, in _evaluate_standard
    return op(a, b)
  File "/home/airflow/.local/lib/python3.6/site-packages/pandas/core/ops/roperator.py", line 13, in rsub
    return right - left
TypeError: unsupported operand type(s) for -: 'datetime.datetime' and 'str'

During handling of the above exception, another exception occurred:

Traceback (most recent call last):
  File "/home/airflow/.local/lib/python3.6/site-packages/airflow/models/taskinstance.py", line 1157, in _run_raw_task
    self._prepare_and_execute_task_with_callbacks(context, task)
  File "/home/airflow/.local/lib/python3.6/site-packages/airflow/models/taskinstance.py", line 1331, in _prepare_and_execute_task_with_callbacks
    result = self._execute_task(context, task_copy)
  File "/home/airflow/.local/lib/python3.6/site-packages/airflow/models/taskinstance.py", line 1361, in _execute_task
    result = task_copy.execute(context=context)
  File "/home/airflow/.local/lib/python3.6/site-packages/airflow/operators/python.py", line 150, in execute
    return_value = self.execute_callable()
  File "/home/airflow/.local/lib/python3.6/site-packages/airflow/operators/python.py", line 161, in execute_callable
    return self.python_callable(*self.op_args, **self.op_kwargs)
  File "/opt/airflow/dags/ELT.py", line 63, in transform
    df['days_worked'] = (today - df['hire_date']).dt.days
  File "/home/airflow/.local/lib/python3.6/site-packages/pandas/core/ops/common.py", line 65, in new_method
    return method(self, other)
  File "/home/airflow/.local/lib/python3.6/site-packages/pandas/core/ops/__init__.py", line 343, in wrapper
    result = arithmetic_op(lvalues, rvalues, op)
  File "/home/airflow/.local/lib/python3.6/site-packages/pandas/core/ops/array_ops.py", line 190, in arithmetic_op
    res_values = na_arithmetic_op(lvalues, rvalues, op)
  File "/home/airflow/.local/lib/python3.6/site-packages/pandas/core/ops/array_ops.py", line 150, in na_arithmetic_op
    result = masked_arith_op(left, right, op)
  File "/home/airflow/.local/lib/python3.6/site-packages/pandas/core/ops/array_ops.py", line 112, in masked_arith_op
    result[mask] = op(xrav[mask], y)
  File "/home/airflow/.local/lib/python3.6/site-packages/pandas/core/ops/roperator.py", line 13, in rsub
    return right - left
TypeError: unsupported operand type(s) for -: 'datetime.datetime' and 'str'
[2024-07-21 03:42:08,641] {taskinstance.py:1551} INFO - Marking task as UP_FOR_RETRY. dag_id=ETL_task, task_id=caculate_square_amount, execution_date=20210811T000000, start_date=20240721T034208, end_date=20240721T034208
[2024-07-21 03:42:08,724] {logging_mixin.py:104} WARNING - /home/***/.local/lib/python3.6/site-packages/***/utils/email.py:102 PendingDeprecationWarning: Fetching SMTP credentials from configuration variables will be deprecated in a future release. Please set credentials using a connection instead.
[2024-07-21 03:42:08,724] {configuration.py:365} WARNING - section/key [smtp/smtp_user] not found in config
[2024-07-21 03:42:08,725] {email.py:208} INFO - Email alerting: attempt 1
[2024-07-21 03:42:08,736] {configuration.py:365} WARNING - section/key [smtp/smtp_user] not found in config
[2024-07-21 03:42:08,736] {email.py:208} INFO - Email alerting: attempt 1
[2024-07-21 03:42:08,737] {taskinstance.py:1557} ERROR - Failed to send email to: ['trihx2003@gmail.com']
Traceback (most recent call last):
  File "/home/airflow/.local/lib/python3.6/site-packages/pandas/core/ops/array_ops.py", line 143, in na_arithmetic_op
    result = expressions.evaluate(op, left, right)
  File "/home/airflow/.local/lib/python3.6/site-packages/pandas/core/computation/expressions.py", line 233, in evaluate
    return _evaluate(op, op_str, a, b)  # type: ignore
  File "/home/airflow/.local/lib/python3.6/site-packages/pandas/core/computation/expressions.py", line 68, in _evaluate_standard
    return op(a, b)
  File "/home/airflow/.local/lib/python3.6/site-packages/pandas/core/ops/roperator.py", line 13, in rsub
    return right - left
TypeError: unsupported operand type(s) for -: 'datetime.datetime' and 'str'

During handling of the above exception, another exception occurred:

Traceback (most recent call last):
  File "/home/airflow/.local/lib/python3.6/site-packages/airflow/models/taskinstance.py", line 1157, in _run_raw_task
    self._prepare_and_execute_task_with_callbacks(context, task)
  File "/home/airflow/.local/lib/python3.6/site-packages/airflow/models/taskinstance.py", line 1331, in _prepare_and_execute_task_with_callbacks
    result = self._execute_task(context, task_copy)
  File "/home/airflow/.local/lib/python3.6/site-packages/airflow/models/taskinstance.py", line 1361, in _execute_task
    result = task_copy.execute(context=context)
  File "/home/airflow/.local/lib/python3.6/site-packages/airflow/operators/python.py", line 150, in execute
    return_value = self.execute_callable()
  File "/home/airflow/.local/lib/python3.6/site-packages/airflow/operators/python.py", line 161, in execute_callable
    return self.python_callable(*self.op_args, **self.op_kwargs)
  File "/opt/airflow/dags/ELT.py", line 63, in transform
    df['days_worked'] = (today - df['hire_date']).dt.days
  File "/home/airflow/.local/lib/python3.6/site-packages/pandas/core/ops/common.py", line 65, in new_method
    return method(self, other)
  File "/home/airflow/.local/lib/python3.6/site-packages/pandas/core/ops/__init__.py", line 343, in wrapper
    result = arithmetic_op(lvalues, rvalues, op)
  File "/home/airflow/.local/lib/python3.6/site-packages/pandas/core/ops/array_ops.py", line 190, in arithmetic_op
    res_values = na_arithmetic_op(lvalues, rvalues, op)
  File "/home/airflow/.local/lib/python3.6/site-packages/pandas/core/ops/array_ops.py", line 150, in na_arithmetic_op
    result = masked_arith_op(left, right, op)
  File "/home/airflow/.local/lib/python3.6/site-packages/pandas/core/ops/array_ops.py", line 112, in masked_arith_op
    result[mask] = op(xrav[mask], y)
  File "/home/airflow/.local/lib/python3.6/site-packages/pandas/core/ops/roperator.py", line 13, in rsub
    return right - left
TypeError: unsupported operand type(s) for -: 'datetime.datetime' and 'str'

During handling of the above exception, another exception occurred:

Traceback (most recent call last):
  File "/home/airflow/.local/lib/python3.6/site-packages/airflow/models/taskinstance.py", line 1896, in email_alert
    send_email(self.task.email, subject, html_content)
  File "/home/airflow/.local/lib/python3.6/site-packages/airflow/utils/email.py", line 66, in send_email
    **kwargs,
  File "/home/airflow/.local/lib/python3.6/site-packages/airflow/utils/email.py", line 102, in send_email_smtp
    send_mime_email(e_from=smtp_mail_from, e_to=recipients, mime_msg=msg, conn_id=conn_id, dryrun=dryrun)
  File "/home/airflow/.local/lib/python3.6/site-packages/airflow/utils/email.py", line 210, in send_mime_email
    conn = _get_smtp_connection(smtp_host, smtp_port, smtp_timeout, smtp_ssl)
  File "/home/airflow/.local/lib/python3.6/site-packages/airflow/utils/email.py", line 244, in _get_smtp_connection
    else smtplib.SMTP(host=host, port=port, timeout=timeout)
  File "/usr/local/lib/python3.6/smtplib.py", line 251, in __init__
    (code, msg) = self.connect(host, port)
  File "/usr/local/lib/python3.6/smtplib.py", line 336, in connect
    self.sock = self._get_socket(host, port, self.timeout)
  File "/usr/local/lib/python3.6/smtplib.py", line 307, in _get_socket
    self.source_address)
  File "/usr/local/lib/python3.6/socket.py", line 724, in create_connection
    raise err
  File "/usr/local/lib/python3.6/socket.py", line 713, in create_connection
    sock.connect(sa)
OSError: [Errno 99] Cannot assign requested address

During handling of the above exception, another exception occurred:

Traceback (most recent call last):
  File "/home/airflow/.local/lib/python3.6/site-packages/airflow/models/taskinstance.py", line 1555, in handle_failure
    self.email_alert(error)
  File "/home/airflow/.local/lib/python3.6/site-packages/airflow/models/taskinstance.py", line 1898, in email_alert
    send_email(self.task.email, subject, html_content_err)
  File "/home/airflow/.local/lib/python3.6/site-packages/airflow/utils/email.py", line 66, in send_email
    **kwargs,
  File "/home/airflow/.local/lib/python3.6/site-packages/airflow/utils/email.py", line 102, in send_email_smtp
    send_mime_email(e_from=smtp_mail_from, e_to=recipients, mime_msg=msg, conn_id=conn_id, dryrun=dryrun)
  File "/home/airflow/.local/lib/python3.6/site-packages/airflow/utils/email.py", line 210, in send_mime_email
    conn = _get_smtp_connection(smtp_host, smtp_port, smtp_timeout, smtp_ssl)
  File "/home/airflow/.local/lib/python3.6/site-packages/airflow/utils/email.py", line 244, in _get_smtp_connection
    else smtplib.SMTP(host=host, port=port, timeout=timeout)
  File "/usr/local/lib/python3.6/smtplib.py", line 251, in __init__
    (code, msg) = self.connect(host, port)
  File "/usr/local/lib/python3.6/smtplib.py", line 336, in connect
    self.sock = self._get_socket(host, port, self.timeout)
  File "/usr/local/lib/python3.6/smtplib.py", line 307, in _get_socket
    self.source_address)
  File "/usr/local/lib/python3.6/socket.py", line 724, in create_connection
    raise err
  File "/usr/local/lib/python3.6/socket.py", line 713, in create_connection
    sock.connect(sa)
OSError: [Errno 99] Cannot assign requested address
[2024-07-21 03:42:08,777] {local_task_job.py:149} INFO - Task exited with return code 1
