[2024-07-21 03:51:17,393] {taskinstance.py:896} INFO - Dependencies all met for <TaskInstance: ETL_task.email_to_admin 2021-06-01T00:00:00+00:00 [queued]>
[2024-07-21 03:51:17,408] {taskinstance.py:896} INFO - Dependencies all met for <TaskInstance: ETL_task.email_to_admin 2021-06-01T00:00:00+00:00 [queued]>
[2024-07-21 03:51:17,408] {taskinstance.py:1087} INFO - 
--------------------------------------------------------------------------------
[2024-07-21 03:51:17,408] {taskinstance.py:1088} INFO - Starting attempt 1 of 2
[2024-07-21 03:51:17,409] {taskinstance.py:1089} INFO - 
--------------------------------------------------------------------------------
[2024-07-21 03:51:17,419] {taskinstance.py:1107} INFO - Executing <Task(PythonOperator): email_to_admin> on 2021-06-01T00:00:00+00:00
[2024-07-21 03:51:17,425] {standard_task_runner.py:52} INFO - Started process 1236 to run task
[2024-07-21 03:51:17,429] {standard_task_runner.py:76} INFO - Running: ['***', 'tasks', 'run', 'ETL_task', 'email_to_admin', '2021-06-01T00:00:00+00:00', '--job-id', '215', '--pool', 'default_pool', '--raw', '--subdir', 'DAGS_FOLDER/ELT.py', '--cfg-path', '/tmp/tmpkx5h_lq9', '--error-file', '/tmp/tmpvb9bvsy5']
[2024-07-21 03:51:17,430] {standard_task_runner.py:77} INFO - Job 215: Subtask email_to_admin
[2024-07-21 03:51:17,477] {logging_mixin.py:104} INFO - Running <TaskInstance: ETL_task.email_to_admin 2021-06-01T00:00:00+00:00 [running]> on host abd747f4a187
[2024-07-21 03:51:17,521] {taskinstance.py:1302} INFO - Exporting the following env vars:
AIRFLOW_CTX_DAG_EMAIL=trihx2003@gmail.com
AIRFLOW_CTX_DAG_OWNER=***
AIRFLOW_CTX_DAG_ID=ETL_task
AIRFLOW_CTX_TASK_ID=email_to_admin
AIRFLOW_CTX_EXECUTION_DATE=2021-06-01T00:00:00+00:00
AIRFLOW_CTX_DAG_RUN_ID=scheduled__2021-06-01T00:00:00+00:00
[2024-07-21 03:51:18,241] {taskinstance.py:1501} ERROR - Task failed with exception
Traceback (most recent call last):
  File "/opt/airflow/dags/ELT.py", line 98, in email
    response = sg.send(message)
  File "/home/airflow/.local/lib/python3.6/site-packages/sendgrid/base_interface.py", line 62, in send
    return self.client.mail.send.post(request_body=message)
  File "/home/airflow/.local/lib/python3.6/site-packages/python_http_client/client.py", line 277, in http_request
    self._make_request(opener, request, timeout=timeout)
  File "/home/airflow/.local/lib/python3.6/site-packages/python_http_client/client.py", line 184, in _make_request
    raise exc
python_http_client.exceptions.UnauthorizedError: HTTP Error 401: Unauthorized

During handling of the above exception, another exception occurred:

Traceback (most recent call last):
  File "/home/airflow/.local/lib/python3.6/site-packages/airflow/models/taskinstance.py", line 1157, in _run_raw_task
    self._prepare_and_execute_task_with_callbacks(context, task)
  File "/home/airflow/.local/lib/python3.6/site-packages/airflow/models/taskinstance.py", line 1331, in _prepare_and_execute_task_with_callbacks
    result = self._execute_task(context, task_copy)
  File "/home/airflow/.local/lib/python3.6/site-packages/airflow/models/taskinstance.py", line 1361, in _execute_task
    result = task_copy.execute(context=context)
  File "/home/airflow/.local/lib/python3.6/site-packages/airflow/operators/python.py", line 150, in execute
    return_value = self.execute_callable()
  File "/home/airflow/.local/lib/python3.6/site-packages/airflow/operators/python.py", line 161, in execute_callable
    return self.python_callable(*self.op_args, **self.op_kwargs)
  File "/opt/airflow/dags/ELT.py", line 104, in email
    print(e.message)
AttributeError: 'UnauthorizedError' object has no attribute 'message'
[2024-07-21 03:51:18,248] {taskinstance.py:1551} INFO - Marking task as UP_FOR_RETRY. dag_id=ETL_task, task_id=email_to_admin, execution_date=20210601T000000, start_date=20240721T035117, end_date=20240721T035118
[2024-07-21 03:51:18,297] {logging_mixin.py:104} WARNING - /home/***/.local/lib/python3.6/site-packages/***/utils/email.py:102 PendingDeprecationWarning: Fetching SMTP credentials from configuration variables will be deprecated in a future release. Please set credentials using a connection instead.
[2024-07-21 03:51:18,298] {configuration.py:365} WARNING - section/key [smtp/smtp_user] not found in config
[2024-07-21 03:51:18,298] {email.py:208} INFO - Email alerting: attempt 1
[2024-07-21 03:51:18,306] {configuration.py:365} WARNING - section/key [smtp/smtp_user] not found in config
[2024-07-21 03:51:18,307] {email.py:208} INFO - Email alerting: attempt 1
[2024-07-21 03:51:18,307] {taskinstance.py:1557} ERROR - Failed to send email to: ['trihx2003@gmail.com']
Traceback (most recent call last):
  File "/opt/airflow/dags/ELT.py", line 98, in email
    response = sg.send(message)
  File "/home/airflow/.local/lib/python3.6/site-packages/sendgrid/base_interface.py", line 62, in send
    return self.client.mail.send.post(request_body=message)
  File "/home/airflow/.local/lib/python3.6/site-packages/python_http_client/client.py", line 277, in http_request
    self._make_request(opener, request, timeout=timeout)
  File "/home/airflow/.local/lib/python3.6/site-packages/python_http_client/client.py", line 184, in _make_request
    raise exc
python_http_client.exceptions.UnauthorizedError: HTTP Error 401: Unauthorized

During handling of the above exception, another exception occurred:

Traceback (most recent call last):
  File "/home/airflow/.local/lib/python3.6/site-packages/airflow/models/taskinstance.py", line 1157, in _run_raw_task
    self._prepare_and_execute_task_with_callbacks(context, task)
  File "/home/airflow/.local/lib/python3.6/site-packages/airflow/models/taskinstance.py", line 1331, in _prepare_and_execute_task_with_callbacks
    result = self._execute_task(context, task_copy)
  File "/home/airflow/.local/lib/python3.6/site-packages/airflow/models/taskinstance.py", line 1361, in _execute_task
    result = task_copy.execute(context=context)
  File "/home/airflow/.local/lib/python3.6/site-packages/airflow/operators/python.py", line 150, in execute
    return_value = self.execute_callable()
  File "/home/airflow/.local/lib/python3.6/site-packages/airflow/operators/python.py", line 161, in execute_callable
    return self.python_callable(*self.op_args, **self.op_kwargs)
  File "/opt/airflow/dags/ELT.py", line 104, in email
    print(e.message)
AttributeError: 'UnauthorizedError' object has no attribute 'message'

During handling of the above exception, another exception occurred:

Traceback (most recent call last):
  File "/home/airflow/.local/lib/python3.6/site-packages/airflow/models/taskinstance.py", line 1896, in email_alert
    send_email(self.task.email, subject, html_content)
  File "/home/airflow/.local/lib/python3.6/site-packages/airflow/utils/email.py", line 66, in send_email
    **kwargs,
  File "/home/airflow/.local/lib/python3.6/site-packages/airflow/utils/email.py", line 102, in send_email_smtp
    send_mime_email(e_from=smtp_mail_from, e_to=recipients, mime_msg=msg, conn_id=conn_id, dryrun=dryrun)
  File "/home/airflow/.local/lib/python3.6/site-packages/airflow/utils/email.py", line 210, in send_mime_email
    conn = _get_smtp_connection(smtp_host, smtp_port, smtp_timeout, smtp_ssl)
  File "/home/airflow/.local/lib/python3.6/site-packages/airflow/utils/email.py", line 244, in _get_smtp_connection
    else smtplib.SMTP(host=host, port=port, timeout=timeout)
  File "/usr/local/lib/python3.6/smtplib.py", line 251, in __init__
    (code, msg) = self.connect(host, port)
  File "/usr/local/lib/python3.6/smtplib.py", line 336, in connect
    self.sock = self._get_socket(host, port, self.timeout)
  File "/usr/local/lib/python3.6/smtplib.py", line 307, in _get_socket
    self.source_address)
  File "/usr/local/lib/python3.6/socket.py", line 724, in create_connection
    raise err
  File "/usr/local/lib/python3.6/socket.py", line 713, in create_connection
    sock.connect(sa)
OSError: [Errno 99] Cannot assign requested address

During handling of the above exception, another exception occurred:

Traceback (most recent call last):
  File "/home/airflow/.local/lib/python3.6/site-packages/airflow/models/taskinstance.py", line 1555, in handle_failure
    self.email_alert(error)
  File "/home/airflow/.local/lib/python3.6/site-packages/airflow/models/taskinstance.py", line 1898, in email_alert
    send_email(self.task.email, subject, html_content_err)
  File "/home/airflow/.local/lib/python3.6/site-packages/airflow/utils/email.py", line 66, in send_email
    **kwargs,
  File "/home/airflow/.local/lib/python3.6/site-packages/airflow/utils/email.py", line 102, in send_email_smtp
    send_mime_email(e_from=smtp_mail_from, e_to=recipients, mime_msg=msg, conn_id=conn_id, dryrun=dryrun)
  File "/home/airflow/.local/lib/python3.6/site-packages/airflow/utils/email.py", line 210, in send_mime_email
    conn = _get_smtp_connection(smtp_host, smtp_port, smtp_timeout, smtp_ssl)
  File "/home/airflow/.local/lib/python3.6/site-packages/airflow/utils/email.py", line 244, in _get_smtp_connection
    else smtplib.SMTP(host=host, port=port, timeout=timeout)
  File "/usr/local/lib/python3.6/smtplib.py", line 251, in __init__
    (code, msg) = self.connect(host, port)
  File "/usr/local/lib/python3.6/smtplib.py", line 336, in connect
    self.sock = self._get_socket(host, port, self.timeout)
  File "/usr/local/lib/python3.6/smtplib.py", line 307, in _get_socket
    self.source_address)
  File "/usr/local/lib/python3.6/socket.py", line 724, in create_connection
    raise err
  File "/usr/local/lib/python3.6/socket.py", line 713, in create_connection
    sock.connect(sa)
OSError: [Errno 99] Cannot assign requested address
[2024-07-21 03:51:18,363] {local_task_job.py:149} INFO - Task exited with return code 1
