[2024-07-21 03:23:45,321] {taskinstance.py:896} INFO - Dependencies all met for <TaskInstance: ETL_task.load_from_mysql 2024-07-21T03:14:38.241455+00:00 [queued]>
[2024-07-21 03:23:45,332] {taskinstance.py:896} INFO - Dependencies all met for <TaskInstance: ETL_task.load_from_mysql 2024-07-21T03:14:38.241455+00:00 [queued]>
[2024-07-21 03:23:45,333] {taskinstance.py:1087} INFO - 
--------------------------------------------------------------------------------
[2024-07-21 03:23:45,333] {taskinstance.py:1088} INFO - Starting attempt 2 of 2
[2024-07-21 03:23:45,334] {taskinstance.py:1089} INFO - 
--------------------------------------------------------------------------------
[2024-07-21 03:23:45,348] {taskinstance.py:1107} INFO - Executing <Task(PythonOperator): load_from_mysql> on 2024-07-21T03:14:38.241455+00:00
[2024-07-21 03:23:45,353] {standard_task_runner.py:52} INFO - Started process 1322 to run task
[2024-07-21 03:23:45,366] {standard_task_runner.py:76} INFO - Running: ['***', 'tasks', 'run', 'ETL_task', 'load_from_mysql', '2024-07-21T03:14:38.241455+00:00', '--job-id', '74', '--pool', 'default_pool', '--raw', '--subdir', 'DAGS_FOLDER/ELT.py', '--cfg-path', '/tmp/tmpeip1rhbl', '--error-file', '/tmp/tmpgw0a285k']
[2024-07-21 03:23:45,367] {standard_task_runner.py:77} INFO - Job 74: Subtask load_from_mysql
[2024-07-21 03:23:45,465] {logging_mixin.py:104} INFO - Running <TaskInstance: ETL_task.load_from_mysql 2024-07-21T03:14:38.241455+00:00 [running]> on host 1a73cfe77f5e
[2024-07-21 03:23:45,533] {taskinstance.py:1302} INFO - Exporting the following env vars:
AIRFLOW_CTX_DAG_EMAIL=trihx2003@gmail.com
AIRFLOW_CTX_DAG_OWNER=***
AIRFLOW_CTX_DAG_ID=ETL_task
AIRFLOW_CTX_TASK_ID=load_from_mysql
AIRFLOW_CTX_EXECUTION_DATE=2024-07-21T03:14:38.241455+00:00
AIRFLOW_CTX_DAG_RUN_ID=manual__2024-07-21T03:14:38.241455+00:00
[2024-07-21 03:23:45,842] {taskinstance.py:1501} ERROR - Task failed with exception
Traceback (most recent call last):
  File "/home/airflow/.local/lib/python3.6/site-packages/airflow/models/taskinstance.py", line 1157, in _run_raw_task
    self._prepare_and_execute_task_with_callbacks(context, task)
  File "/home/airflow/.local/lib/python3.6/site-packages/airflow/models/taskinstance.py", line 1331, in _prepare_and_execute_task_with_callbacks
    result = self._execute_task(context, task_copy)
  File "/home/airflow/.local/lib/python3.6/site-packages/airflow/models/taskinstance.py", line 1361, in _execute_task
    result = task_copy.execute(context=context)
  File "/home/airflow/.local/lib/python3.6/site-packages/airflow/operators/python.py", line 150, in execute
    return_value = self.execute_callable()
  File "/home/airflow/.local/lib/python3.6/site-packages/airflow/operators/python.py", line 161, in execute_callable
    return self.python_callable(*self.op_args, **self.op_kwargs)
  File "/opt/airflow/dags/ELT.py", line 27, in extract
    cur.execute(sql)
  File "/home/airflow/.local/lib/python3.6/site-packages/pymysql/cursors.py", line 148, in execute
    result = self._query(query)
  File "/home/airflow/.local/lib/python3.6/site-packages/pymysql/cursors.py", line 310, in _query
    conn.query(q)
  File "/home/airflow/.local/lib/python3.6/site-packages/pymysql/connections.py", line 548, in query
    self._affected_rows = self._read_query_result(unbuffered=unbuffered)
  File "/home/airflow/.local/lib/python3.6/site-packages/pymysql/connections.py", line 775, in _read_query_result
    result.read()
  File "/home/airflow/.local/lib/python3.6/site-packages/pymysql/connections.py", line 1156, in read
    first_packet = self.connection._read_packet()
  File "/home/airflow/.local/lib/python3.6/site-packages/pymysql/connections.py", line 725, in _read_packet
    packet.raise_for_error()
  File "/home/airflow/.local/lib/python3.6/site-packages/pymysql/protocol.py", line 221, in raise_for_error
    err.raise_mysql_exception(self._data)
  File "/home/airflow/.local/lib/python3.6/site-packages/pymysql/err.py", line 143, in raise_mysql_exception
    raise errorclass(errno, errval)
pymysql.err.ProgrammingError: (1146, "Table 'my_database.my_database' doesn't exist")
[2024-07-21 03:23:45,854] {taskinstance.py:1551} INFO - Marking task as FAILED. dag_id=ETL_task, task_id=load_from_mysql, execution_date=20240721T031438, start_date=20240721T032345, end_date=20240721T032345
[2024-07-21 03:23:45,890] {logging_mixin.py:104} WARNING - /home/***/.local/lib/python3.6/site-packages/***/utils/email.py:102 PendingDeprecationWarning: Fetching SMTP credentials from configuration variables will be deprecated in a future release. Please set credentials using a connection instead.
[2024-07-21 03:23:45,890] {configuration.py:365} WARNING - section/key [smtp/smtp_user] not found in config
[2024-07-21 03:23:45,891] {email.py:208} INFO - Email alerting: attempt 1
[2024-07-21 03:23:45,899] {configuration.py:365} WARNING - section/key [smtp/smtp_user] not found in config
[2024-07-21 03:23:45,899] {email.py:208} INFO - Email alerting: attempt 1
[2024-07-21 03:23:45,900] {taskinstance.py:1557} ERROR - Failed to send email to: ['trihx2003@gmail.com']
Traceback (most recent call last):
  File "/home/airflow/.local/lib/python3.6/site-packages/airflow/models/taskinstance.py", line 1157, in _run_raw_task
    self._prepare_and_execute_task_with_callbacks(context, task)
  File "/home/airflow/.local/lib/python3.6/site-packages/airflow/models/taskinstance.py", line 1331, in _prepare_and_execute_task_with_callbacks
    result = self._execute_task(context, task_copy)
  File "/home/airflow/.local/lib/python3.6/site-packages/airflow/models/taskinstance.py", line 1361, in _execute_task
    result = task_copy.execute(context=context)
  File "/home/airflow/.local/lib/python3.6/site-packages/airflow/operators/python.py", line 150, in execute
    return_value = self.execute_callable()
  File "/home/airflow/.local/lib/python3.6/site-packages/airflow/operators/python.py", line 161, in execute_callable
    return self.python_callable(*self.op_args, **self.op_kwargs)
  File "/opt/airflow/dags/ELT.py", line 27, in extract
    cur.execute(sql)
  File "/home/airflow/.local/lib/python3.6/site-packages/pymysql/cursors.py", line 148, in execute
    result = self._query(query)
  File "/home/airflow/.local/lib/python3.6/site-packages/pymysql/cursors.py", line 310, in _query
    conn.query(q)
  File "/home/airflow/.local/lib/python3.6/site-packages/pymysql/connections.py", line 548, in query
    self._affected_rows = self._read_query_result(unbuffered=unbuffered)
  File "/home/airflow/.local/lib/python3.6/site-packages/pymysql/connections.py", line 775, in _read_query_result
    result.read()
  File "/home/airflow/.local/lib/python3.6/site-packages/pymysql/connections.py", line 1156, in read
    first_packet = self.connection._read_packet()
  File "/home/airflow/.local/lib/python3.6/site-packages/pymysql/connections.py", line 725, in _read_packet
    packet.raise_for_error()
  File "/home/airflow/.local/lib/python3.6/site-packages/pymysql/protocol.py", line 221, in raise_for_error
    err.raise_mysql_exception(self._data)
  File "/home/airflow/.local/lib/python3.6/site-packages/pymysql/err.py", line 143, in raise_mysql_exception
    raise errorclass(errno, errval)
pymysql.err.ProgrammingError: (1146, "Table 'my_database.my_database' doesn't exist")

During handling of the above exception, another exception occurred:

Traceback (most recent call last):
  File "/home/airflow/.local/lib/python3.6/site-packages/airflow/models/taskinstance.py", line 1896, in email_alert
    send_email(self.task.email, subject, html_content)
  File "/home/airflow/.local/lib/python3.6/site-packages/airflow/utils/email.py", line 66, in send_email
    **kwargs,
  File "/home/airflow/.local/lib/python3.6/site-packages/airflow/utils/email.py", line 102, in send_email_smtp
    send_mime_email(e_from=smtp_mail_from, e_to=recipients, mime_msg=msg, conn_id=conn_id, dryrun=dryrun)
  File "/home/airflow/.local/lib/python3.6/site-packages/airflow/utils/email.py", line 210, in send_mime_email
    conn = _get_smtp_connection(smtp_host, smtp_port, smtp_timeout, smtp_ssl)
  File "/home/airflow/.local/lib/python3.6/site-packages/airflow/utils/email.py", line 244, in _get_smtp_connection
    else smtplib.SMTP(host=host, port=port, timeout=timeout)
  File "/usr/local/lib/python3.6/smtplib.py", line 251, in __init__
    (code, msg) = self.connect(host, port)
  File "/usr/local/lib/python3.6/smtplib.py", line 336, in connect
    self.sock = self._get_socket(host, port, self.timeout)
  File "/usr/local/lib/python3.6/smtplib.py", line 307, in _get_socket
    self.source_address)
  File "/usr/local/lib/python3.6/socket.py", line 724, in create_connection
    raise err
  File "/usr/local/lib/python3.6/socket.py", line 713, in create_connection
    sock.connect(sa)
OSError: [Errno 99] Cannot assign requested address

During handling of the above exception, another exception occurred:

Traceback (most recent call last):
  File "/home/airflow/.local/lib/python3.6/site-packages/airflow/models/taskinstance.py", line 1555, in handle_failure
    self.email_alert(error)
  File "/home/airflow/.local/lib/python3.6/site-packages/airflow/models/taskinstance.py", line 1898, in email_alert
    send_email(self.task.email, subject, html_content_err)
  File "/home/airflow/.local/lib/python3.6/site-packages/airflow/utils/email.py", line 66, in send_email
    **kwargs,
  File "/home/airflow/.local/lib/python3.6/site-packages/airflow/utils/email.py", line 102, in send_email_smtp
    send_mime_email(e_from=smtp_mail_from, e_to=recipients, mime_msg=msg, conn_id=conn_id, dryrun=dryrun)
  File "/home/airflow/.local/lib/python3.6/site-packages/airflow/utils/email.py", line 210, in send_mime_email
    conn = _get_smtp_connection(smtp_host, smtp_port, smtp_timeout, smtp_ssl)
  File "/home/airflow/.local/lib/python3.6/site-packages/airflow/utils/email.py", line 244, in _get_smtp_connection
    else smtplib.SMTP(host=host, port=port, timeout=timeout)
  File "/usr/local/lib/python3.6/smtplib.py", line 251, in __init__
    (code, msg) = self.connect(host, port)
  File "/usr/local/lib/python3.6/smtplib.py", line 336, in connect
    self.sock = self._get_socket(host, port, self.timeout)
  File "/usr/local/lib/python3.6/smtplib.py", line 307, in _get_socket
    self.source_address)
  File "/usr/local/lib/python3.6/socket.py", line 724, in create_connection
    raise err
  File "/usr/local/lib/python3.6/socket.py", line 713, in create_connection
    sock.connect(sa)
OSError: [Errno 99] Cannot assign requested address
[2024-07-21 03:23:45,938] {local_task_job.py:149} INFO - Task exited with return code 1
