[2024-07-21 03:13:53,531] {taskinstance.py:896} INFO - Dependencies all met for <TaskInstance: ETL_task.load_from_mysql 2021-06-11T00:00:00+00:00 [queued]>
[2024-07-21 03:13:53,561] {taskinstance.py:896} INFO - Dependencies all met for <TaskInstance: ETL_task.load_from_mysql 2021-06-11T00:00:00+00:00 [queued]>
[2024-07-21 03:13:53,562] {taskinstance.py:1087} INFO - 
--------------------------------------------------------------------------------
[2024-07-21 03:13:53,562] {taskinstance.py:1088} INFO - Starting attempt 1 of 2
[2024-07-21 03:13:53,563] {taskinstance.py:1089} INFO - 
--------------------------------------------------------------------------------
[2024-07-21 03:13:53,587] {taskinstance.py:1107} INFO - Executing <Task(PythonOperator): load_from_mysql> on 2021-06-11T00:00:00+00:00
[2024-07-21 03:13:53,596] {standard_task_runner.py:52} INFO - Started process 251 to run task
[2024-07-21 03:13:53,606] {standard_task_runner.py:76} INFO - Running: ['***', 'tasks', 'run', 'ETL_task', 'load_from_mysql', '2021-06-11T00:00:00+00:00', '--job-id', '36', '--pool', 'default_pool', '--raw', '--subdir', 'DAGS_FOLDER/ELT.py', '--cfg-path', '/tmp/tmpkf7i3gko', '--error-file', '/tmp/tmp_1svgif3']
[2024-07-21 03:13:53,611] {standard_task_runner.py:77} INFO - Job 36: Subtask load_from_mysql
[2024-07-21 03:13:53,686] {logging_mixin.py:104} INFO - Running <TaskInstance: ETL_task.load_from_mysql 2021-06-11T00:00:00+00:00 [running]> on host 1a73cfe77f5e
[2024-07-21 03:13:53,798] {taskinstance.py:1302} INFO - Exporting the following env vars:
AIRFLOW_CTX_DAG_EMAIL=trihx2003@gmail.com
AIRFLOW_CTX_DAG_OWNER=***
AIRFLOW_CTX_DAG_ID=ETL_task
AIRFLOW_CTX_TASK_ID=load_from_mysql
AIRFLOW_CTX_EXECUTION_DATE=2021-06-11T00:00:00+00:00
AIRFLOW_CTX_DAG_RUN_ID=scheduled__2021-06-11T00:00:00+00:00
[2024-07-21 03:13:53,813] {taskinstance.py:1501} ERROR - Task failed with exception
Traceback (most recent call last):
  File "/home/airflow/.local/lib/python3.6/site-packages/pymysql/connections.py", line 614, in connect
    (self.host, self.port), self.connect_timeout, **kwargs
  File "/usr/local/lib/python3.6/socket.py", line 724, in create_connection
    raise err
  File "/usr/local/lib/python3.6/socket.py", line 713, in create_connection
    sock.connect(sa)
OSError: [Errno 99] Cannot assign requested address

During handling of the above exception, another exception occurred:

Traceback (most recent call last):
  File "/home/airflow/.local/lib/python3.6/site-packages/airflow/models/taskinstance.py", line 1157, in _run_raw_task
    self._prepare_and_execute_task_with_callbacks(context, task)
  File "/home/airflow/.local/lib/python3.6/site-packages/airflow/models/taskinstance.py", line 1331, in _prepare_and_execute_task_with_callbacks
    result = self._execute_task(context, task_copy)
  File "/home/airflow/.local/lib/python3.6/site-packages/airflow/models/taskinstance.py", line 1361, in _execute_task
    result = task_copy.execute(context=context)
  File "/home/airflow/.local/lib/python3.6/site-packages/airflow/operators/python.py", line 150, in execute
    return_value = self.execute_callable()
  File "/home/airflow/.local/lib/python3.6/site-packages/airflow/operators/python.py", line 161, in execute_callable
    return self.python_callable(*self.op_args, **self.op_kwargs)
  File "/opt/airflow/dags/ELT.py", line 20, in extract
    db = pymysql.connect(**db_opts)
  File "/home/airflow/.local/lib/python3.6/site-packages/pymysql/connections.py", line 353, in __init__
    self.connect()
  File "/home/airflow/.local/lib/python3.6/site-packages/pymysql/connections.py", line 664, in connect
    raise exc
pymysql.err.OperationalError: (2003, "Can't connect to MySQL server on 'localhost' ([Errno 99] Cannot assign requested address)")
[2024-07-21 03:13:53,821] {taskinstance.py:1551} INFO - Marking task as UP_FOR_RETRY. dag_id=ETL_task, task_id=load_from_mysql, execution_date=20210611T000000, start_date=20240721T031353, end_date=20240721T031353
[2024-07-21 03:13:53,914] {logging_mixin.py:104} WARNING - /home/***/.local/lib/python3.6/site-packages/***/utils/email.py:102 PendingDeprecationWarning: Fetching SMTP credentials from configuration variables will be deprecated in a future release. Please set credentials using a connection instead.
[2024-07-21 03:13:53,915] {configuration.py:365} WARNING - section/key [smtp/smtp_user] not found in config
[2024-07-21 03:13:53,915] {email.py:208} INFO - Email alerting: attempt 1
[2024-07-21 03:13:53,926] {configuration.py:365} WARNING - section/key [smtp/smtp_user] not found in config
[2024-07-21 03:13:53,927] {email.py:208} INFO - Email alerting: attempt 1
[2024-07-21 03:13:53,927] {taskinstance.py:1557} ERROR - Failed to send email to: ['trihx2003@gmail.com']
Traceback (most recent call last):
  File "/home/airflow/.local/lib/python3.6/site-packages/pymysql/connections.py", line 614, in connect
    (self.host, self.port), self.connect_timeout, **kwargs
  File "/usr/local/lib/python3.6/socket.py", line 724, in create_connection
    raise err
  File "/usr/local/lib/python3.6/socket.py", line 713, in create_connection
    sock.connect(sa)
OSError: [Errno 99] Cannot assign requested address

During handling of the above exception, another exception occurred:

Traceback (most recent call last):
  File "/home/airflow/.local/lib/python3.6/site-packages/airflow/models/taskinstance.py", line 1157, in _run_raw_task
    self._prepare_and_execute_task_with_callbacks(context, task)
  File "/home/airflow/.local/lib/python3.6/site-packages/airflow/models/taskinstance.py", line 1331, in _prepare_and_execute_task_with_callbacks
    result = self._execute_task(context, task_copy)
  File "/home/airflow/.local/lib/python3.6/site-packages/airflow/models/taskinstance.py", line 1361, in _execute_task
    result = task_copy.execute(context=context)
  File "/home/airflow/.local/lib/python3.6/site-packages/airflow/operators/python.py", line 150, in execute
    return_value = self.execute_callable()
  File "/home/airflow/.local/lib/python3.6/site-packages/airflow/operators/python.py", line 161, in execute_callable
    return self.python_callable(*self.op_args, **self.op_kwargs)
  File "/opt/airflow/dags/ELT.py", line 20, in extract
    db = pymysql.connect(**db_opts)
  File "/home/airflow/.local/lib/python3.6/site-packages/pymysql/connections.py", line 353, in __init__
    self.connect()
  File "/home/airflow/.local/lib/python3.6/site-packages/pymysql/connections.py", line 664, in connect
    raise exc
pymysql.err.OperationalError: (2003, "Can't connect to MySQL server on 'localhost' ([Errno 99] Cannot assign requested address)")

During handling of the above exception, another exception occurred:

Traceback (most recent call last):
  File "/home/airflow/.local/lib/python3.6/site-packages/airflow/models/taskinstance.py", line 1896, in email_alert
    send_email(self.task.email, subject, html_content)
  File "/home/airflow/.local/lib/python3.6/site-packages/airflow/utils/email.py", line 66, in send_email
    **kwargs,
  File "/home/airflow/.local/lib/python3.6/site-packages/airflow/utils/email.py", line 102, in send_email_smtp
    send_mime_email(e_from=smtp_mail_from, e_to=recipients, mime_msg=msg, conn_id=conn_id, dryrun=dryrun)
  File "/home/airflow/.local/lib/python3.6/site-packages/airflow/utils/email.py", line 210, in send_mime_email
    conn = _get_smtp_connection(smtp_host, smtp_port, smtp_timeout, smtp_ssl)
  File "/home/airflow/.local/lib/python3.6/site-packages/airflow/utils/email.py", line 244, in _get_smtp_connection
    else smtplib.SMTP(host=host, port=port, timeout=timeout)
  File "/usr/local/lib/python3.6/smtplib.py", line 251, in __init__
    (code, msg) = self.connect(host, port)
  File "/usr/local/lib/python3.6/smtplib.py", line 336, in connect
    self.sock = self._get_socket(host, port, self.timeout)
  File "/usr/local/lib/python3.6/smtplib.py", line 307, in _get_socket
    self.source_address)
  File "/usr/local/lib/python3.6/socket.py", line 724, in create_connection
    raise err
  File "/usr/local/lib/python3.6/socket.py", line 713, in create_connection
    sock.connect(sa)
OSError: [Errno 99] Cannot assign requested address

During handling of the above exception, another exception occurred:

Traceback (most recent call last):
  File "/home/airflow/.local/lib/python3.6/site-packages/airflow/models/taskinstance.py", line 1555, in handle_failure
    self.email_alert(error)
  File "/home/airflow/.local/lib/python3.6/site-packages/airflow/models/taskinstance.py", line 1898, in email_alert
    send_email(self.task.email, subject, html_content_err)
  File "/home/airflow/.local/lib/python3.6/site-packages/airflow/utils/email.py", line 66, in send_email
    **kwargs,
  File "/home/airflow/.local/lib/python3.6/site-packages/airflow/utils/email.py", line 102, in send_email_smtp
    send_mime_email(e_from=smtp_mail_from, e_to=recipients, mime_msg=msg, conn_id=conn_id, dryrun=dryrun)
  File "/home/airflow/.local/lib/python3.6/site-packages/airflow/utils/email.py", line 210, in send_mime_email
    conn = _get_smtp_connection(smtp_host, smtp_port, smtp_timeout, smtp_ssl)
  File "/home/airflow/.local/lib/python3.6/site-packages/airflow/utils/email.py", line 244, in _get_smtp_connection
    else smtplib.SMTP(host=host, port=port, timeout=timeout)
  File "/usr/local/lib/python3.6/smtplib.py", line 251, in __init__
    (code, msg) = self.connect(host, port)
  File "/usr/local/lib/python3.6/smtplib.py", line 336, in connect
    self.sock = self._get_socket(host, port, self.timeout)
  File "/usr/local/lib/python3.6/smtplib.py", line 307, in _get_socket
    self.source_address)
  File "/usr/local/lib/python3.6/socket.py", line 724, in create_connection
    raise err
  File "/usr/local/lib/python3.6/socket.py", line 713, in create_connection
    sock.connect(sa)
OSError: [Errno 99] Cannot assign requested address
[2024-07-21 03:13:53,964] {local_task_job.py:149} INFO - Task exited with return code 1
