[2024-07-21 04:37:04,889] {taskinstance.py:896} INFO - Dependencies all met for <TaskInstance: ETL_task.load_to_postgres 2024-07-21T04:36:53.275562+00:00 [queued]>
[2024-07-21 04:37:04,913] {taskinstance.py:896} INFO - Dependencies all met for <TaskInstance: ETL_task.load_to_postgres 2024-07-21T04:36:53.275562+00:00 [queued]>
[2024-07-21 04:37:04,914] {taskinstance.py:1087} INFO - 
--------------------------------------------------------------------------------
[2024-07-21 04:37:04,914] {taskinstance.py:1088} INFO - Starting attempt 1 of 2
[2024-07-21 04:37:04,914] {taskinstance.py:1089} INFO - 
--------------------------------------------------------------------------------
[2024-07-21 04:37:04,931] {taskinstance.py:1107} INFO - Executing <Task(PythonOperator): load_to_postgres> on 2024-07-21T04:36:53.275562+00:00
[2024-07-21 04:37:04,936] {standard_task_runner.py:52} INFO - Started process 202 to run task
[2024-07-21 04:37:04,940] {standard_task_runner.py:76} INFO - Running: ['***', 'tasks', 'run', 'ETL_task', 'load_to_postgres', '2024-07-21T04:36:53.275562+00:00', '--job-id', '258', '--pool', 'default_pool', '--raw', '--subdir', 'DAGS_FOLDER/ETL.py', '--cfg-path', '/tmp/tmphwm6xumi', '--error-file', '/tmp/tmpbbpaiv5f']
[2024-07-21 04:37:04,941] {standard_task_runner.py:77} INFO - Job 258: Subtask load_to_postgres
[2024-07-21 04:37:04,983] {logging_mixin.py:104} INFO - Running <TaskInstance: ETL_task.load_to_postgres 2024-07-21T04:36:53.275562+00:00 [running]> on host b19ee44dc7cc
[2024-07-21 04:37:05,036] {taskinstance.py:1302} INFO - Exporting the following env vars:
AIRFLOW_CTX_DAG_EMAIL=trihx2003@gmail.com
AIRFLOW_CTX_DAG_OWNER=***
AIRFLOW_CTX_DAG_ID=ETL_task
AIRFLOW_CTX_TASK_ID=load_to_postgres
AIRFLOW_CTX_EXECUTION_DATE=2024-07-21T04:36:53.275562+00:00
AIRFLOW_CTX_DAG_RUN_ID=manual__2024-07-21T04:36:53.275562+00:00
[2024-07-21 04:37:05,114] {taskinstance.py:1501} ERROR - Task failed with exception
Traceback (most recent call last):
  File "/home/airflow/.local/lib/python3.6/site-packages/pandas/core/indexes/base.py", line 2898, in get_loc
    return self._engine.get_loc(casted_key)
  File "pandas/_libs/index.pyx", line 70, in pandas._libs.index.IndexEngine.get_loc
  File "pandas/_libs/index.pyx", line 101, in pandas._libs.index.IndexEngine.get_loc
  File "pandas/_libs/hashtable_class_helper.pxi", line 1675, in pandas._libs.hashtable.PyObjectHashTable.get_item
  File "pandas/_libs/hashtable_class_helper.pxi", line 1683, in pandas._libs.hashtable.PyObjectHashTable.get_item
KeyError: 'name'

The above exception was the direct cause of the following exception:

Traceback (most recent call last):
  File "/home/airflow/.local/lib/python3.6/site-packages/airflow/models/taskinstance.py", line 1157, in _run_raw_task
    self._prepare_and_execute_task_with_callbacks(context, task)
  File "/home/airflow/.local/lib/python3.6/site-packages/airflow/models/taskinstance.py", line 1331, in _prepare_and_execute_task_with_callbacks
    result = self._execute_task(context, task_copy)
  File "/home/airflow/.local/lib/python3.6/site-packages/airflow/models/taskinstance.py", line 1361, in _execute_task
    result = task_copy.execute(context=context)
  File "/home/airflow/.local/lib/python3.6/site-packages/airflow/operators/python.py", line 150, in execute
    return_value = self.execute_callable()
  File "/home/airflow/.local/lib/python3.6/site-packages/airflow/operators/python.py", line 161, in execute_callable
    return self.python_callable(*self.op_args, **self.op_kwargs)
  File "/opt/airflow/dags/ETL.py", line 96, in load_to_postgres
    (int(row['id']), row['name'], row['hire_date'], int(row['days_worked']))
  File "/home/airflow/.local/lib/python3.6/site-packages/pandas/core/series.py", line 882, in __getitem__
    return self._get_value(key)
  File "/home/airflow/.local/lib/python3.6/site-packages/pandas/core/series.py", line 990, in _get_value
    loc = self.index.get_loc(label)
  File "/home/airflow/.local/lib/python3.6/site-packages/pandas/core/indexes/base.py", line 2900, in get_loc
    raise KeyError(key) from err
KeyError: 'name'
[2024-07-21 04:37:05,121] {taskinstance.py:1551} INFO - Marking task as UP_FOR_RETRY. dag_id=ETL_task, task_id=load_to_postgres, execution_date=20240721T043653, start_date=20240721T043704, end_date=20240721T043705
[2024-07-21 04:37:05,152] {logging_mixin.py:104} WARNING - /home/***/.local/lib/python3.6/site-packages/***/utils/email.py:102 PendingDeprecationWarning: Fetching SMTP credentials from configuration variables will be deprecated in a future release. Please set credentials using a connection instead.
[2024-07-21 04:37:05,152] {configuration.py:365} WARNING - section/key [smtp/smtp_user] not found in config
[2024-07-21 04:37:05,153] {email.py:208} INFO - Email alerting: attempt 1
[2024-07-21 04:37:05,163] {configuration.py:365} WARNING - section/key [smtp/smtp_user] not found in config
[2024-07-21 04:37:05,163] {email.py:208} INFO - Email alerting: attempt 1
[2024-07-21 04:37:05,164] {taskinstance.py:1557} ERROR - Failed to send email to: ['trihx2003@gmail.com']
Traceback (most recent call last):
  File "/home/airflow/.local/lib/python3.6/site-packages/pandas/core/indexes/base.py", line 2898, in get_loc
    return self._engine.get_loc(casted_key)
  File "pandas/_libs/index.pyx", line 70, in pandas._libs.index.IndexEngine.get_loc
  File "pandas/_libs/index.pyx", line 101, in pandas._libs.index.IndexEngine.get_loc
  File "pandas/_libs/hashtable_class_helper.pxi", line 1675, in pandas._libs.hashtable.PyObjectHashTable.get_item
  File "pandas/_libs/hashtable_class_helper.pxi", line 1683, in pandas._libs.hashtable.PyObjectHashTable.get_item
KeyError: 'name'

The above exception was the direct cause of the following exception:

Traceback (most recent call last):
  File "/home/airflow/.local/lib/python3.6/site-packages/airflow/models/taskinstance.py", line 1157, in _run_raw_task
    self._prepare_and_execute_task_with_callbacks(context, task)
  File "/home/airflow/.local/lib/python3.6/site-packages/airflow/models/taskinstance.py", line 1331, in _prepare_and_execute_task_with_callbacks
    result = self._execute_task(context, task_copy)
  File "/home/airflow/.local/lib/python3.6/site-packages/airflow/models/taskinstance.py", line 1361, in _execute_task
    result = task_copy.execute(context=context)
  File "/home/airflow/.local/lib/python3.6/site-packages/airflow/operators/python.py", line 150, in execute
    return_value = self.execute_callable()
  File "/home/airflow/.local/lib/python3.6/site-packages/airflow/operators/python.py", line 161, in execute_callable
    return self.python_callable(*self.op_args, **self.op_kwargs)
  File "/opt/airflow/dags/ETL.py", line 96, in load_to_postgres
    (int(row['id']), row['name'], row['hire_date'], int(row['days_worked']))
  File "/home/airflow/.local/lib/python3.6/site-packages/pandas/core/series.py", line 882, in __getitem__
    return self._get_value(key)
  File "/home/airflow/.local/lib/python3.6/site-packages/pandas/core/series.py", line 990, in _get_value
    loc = self.index.get_loc(label)
  File "/home/airflow/.local/lib/python3.6/site-packages/pandas/core/indexes/base.py", line 2900, in get_loc
    raise KeyError(key) from err
KeyError: 'name'

During handling of the above exception, another exception occurred:

Traceback (most recent call last):
  File "/home/airflow/.local/lib/python3.6/site-packages/airflow/models/taskinstance.py", line 1896, in email_alert
    send_email(self.task.email, subject, html_content)
  File "/home/airflow/.local/lib/python3.6/site-packages/airflow/utils/email.py", line 66, in send_email
    **kwargs,
  File "/home/airflow/.local/lib/python3.6/site-packages/airflow/utils/email.py", line 102, in send_email_smtp
    send_mime_email(e_from=smtp_mail_from, e_to=recipients, mime_msg=msg, conn_id=conn_id, dryrun=dryrun)
  File "/home/airflow/.local/lib/python3.6/site-packages/airflow/utils/email.py", line 210, in send_mime_email
    conn = _get_smtp_connection(smtp_host, smtp_port, smtp_timeout, smtp_ssl)
  File "/home/airflow/.local/lib/python3.6/site-packages/airflow/utils/email.py", line 244, in _get_smtp_connection
    else smtplib.SMTP(host=host, port=port, timeout=timeout)
  File "/usr/local/lib/python3.6/smtplib.py", line 251, in __init__
    (code, msg) = self.connect(host, port)
  File "/usr/local/lib/python3.6/smtplib.py", line 336, in connect
    self.sock = self._get_socket(host, port, self.timeout)
  File "/usr/local/lib/python3.6/smtplib.py", line 307, in _get_socket
    self.source_address)
  File "/usr/local/lib/python3.6/socket.py", line 724, in create_connection
    raise err
  File "/usr/local/lib/python3.6/socket.py", line 713, in create_connection
    sock.connect(sa)
OSError: [Errno 99] Cannot assign requested address

During handling of the above exception, another exception occurred:

Traceback (most recent call last):
  File "/home/airflow/.local/lib/python3.6/site-packages/airflow/models/taskinstance.py", line 1555, in handle_failure
    self.email_alert(error)
  File "/home/airflow/.local/lib/python3.6/site-packages/airflow/models/taskinstance.py", line 1898, in email_alert
    send_email(self.task.email, subject, html_content_err)
  File "/home/airflow/.local/lib/python3.6/site-packages/airflow/utils/email.py", line 66, in send_email
    **kwargs,
  File "/home/airflow/.local/lib/python3.6/site-packages/airflow/utils/email.py", line 102, in send_email_smtp
    send_mime_email(e_from=smtp_mail_from, e_to=recipients, mime_msg=msg, conn_id=conn_id, dryrun=dryrun)
  File "/home/airflow/.local/lib/python3.6/site-packages/airflow/utils/email.py", line 210, in send_mime_email
    conn = _get_smtp_connection(smtp_host, smtp_port, smtp_timeout, smtp_ssl)
  File "/home/airflow/.local/lib/python3.6/site-packages/airflow/utils/email.py", line 244, in _get_smtp_connection
    else smtplib.SMTP(host=host, port=port, timeout=timeout)
  File "/usr/local/lib/python3.6/smtplib.py", line 251, in __init__
    (code, msg) = self.connect(host, port)
  File "/usr/local/lib/python3.6/smtplib.py", line 336, in connect
    self.sock = self._get_socket(host, port, self.timeout)
  File "/usr/local/lib/python3.6/smtplib.py", line 307, in _get_socket
    self.source_address)
  File "/usr/local/lib/python3.6/socket.py", line 724, in create_connection
    raise err
  File "/usr/local/lib/python3.6/socket.py", line 713, in create_connection
    sock.connect(sa)
OSError: [Errno 99] Cannot assign requested address
[2024-07-21 04:37:05,192] {local_task_job.py:149} INFO - Task exited with return code 1
